2021-10-28 09:59:26,555 ERROR: Exception on /index [GET] [in c:\users\usuario\documents\projects\playground\flask_microblog\venv\lib\site-packages\flask\app.py:1891]
Traceback (most recent call last):
  File "c:\users\usuario\documents\projects\playground\flask_microblog\venv\lib\site-packages\sqlalchemy\engine\base.py", line 1799, in _execute_context
    self.dialect.do_execute(
  File "c:\users\usuario\documents\projects\playground\flask_microblog\venv\lib\site-packages\sqlalchemy\engine\default.py", line 717, in do_execute
    cursor.execute(statement, parameters)
sqlite3.OperationalError: no such table: followers

The above exception was the direct cause of the following exception:

Traceback (most recent call last):
  File "c:\users\usuario\documents\projects\playground\flask_microblog\venv\lib\site-packages\flask\app.py", line 2447, in wsgi_app
    response = self.full_dispatch_request()
  File "c:\users\usuario\documents\projects\playground\flask_microblog\venv\lib\site-packages\flask\app.py", line 1952, in full_dispatch_request
    rv = self.handle_user_exception(e)
  File "c:\users\usuario\documents\projects\playground\flask_microblog\venv\lib\site-packages\flask\app.py", line 1821, in handle_user_exception
    reraise(exc_type, exc_value, tb)
  File "c:\users\usuario\documents\projects\playground\flask_microblog\venv\lib\site-packages\flask\_compat.py", line 39, in reraise
    raise value
  File "c:\users\usuario\documents\projects\playground\flask_microblog\venv\lib\site-packages\flask\app.py", line 1950, in full_dispatch_request
    rv = self.dispatch_request()
  File "c:\users\usuario\documents\projects\playground\flask_microblog\venv\lib\site-packages\flask\app.py", line 1936, in dispatch_request
    return self.view_functions[rule.endpoint](**req.view_args)
  File "c:\users\usuario\documents\projects\playground\flask_microblog\venv\lib\site-packages\flask_login\utils.py", line 272, in decorated_view
    return func(*args, **kwargs)
  File "C:\Users\usuario\Documents\Projects\playGround\flask_microblog\app\routes.py", line 24, in index
    posts = current_user.followed_posts().all()
  File "c:\users\usuario\documents\projects\playground\flask_microblog\venv\lib\site-packages\sqlalchemy\orm\query.py", line 2711, in all
    return self._iter().all()
  File "c:\users\usuario\documents\projects\playground\flask_microblog\venv\lib\site-packages\sqlalchemy\orm\query.py", line 2846, in _iter
    result = self.session.execute(
  File "c:\users\usuario\documents\projects\playground\flask_microblog\venv\lib\site-packages\sqlalchemy\orm\session.py", line 1689, in execute
    result = conn._execute_20(statement, params or {}, execution_options)
  File "c:\users\usuario\documents\projects\playground\flask_microblog\venv\lib\site-packages\sqlalchemy\engine\base.py", line 1611, in _execute_20
    return meth(self, args_10style, kwargs_10style, execution_options)
  File "c:\users\usuario\documents\projects\playground\flask_microblog\venv\lib\site-packages\sqlalchemy\sql\elements.py", line 325, in _execute_on_connection
    return connection._execute_clauseelement(
  File "c:\users\usuario\documents\projects\playground\flask_microblog\venv\lib\site-packages\sqlalchemy\engine\base.py", line 1478, in _execute_clauseelement
    ret = self._execute_context(
  File "c:\users\usuario\documents\projects\playground\flask_microblog\venv\lib\site-packages\sqlalchemy\engine\base.py", line 1842, in _execute_context
    self._handle_dbapi_exception(
  File "c:\users\usuario\documents\projects\playground\flask_microblog\venv\lib\site-packages\sqlalchemy\engine\base.py", line 2023, in _handle_dbapi_exception
    util.raise_(
  File "c:\users\usuario\documents\projects\playground\flask_microblog\venv\lib\site-packages\sqlalchemy\util\compat.py", line 207, in raise_
    raise exception
  File "c:\users\usuario\documents\projects\playground\flask_microblog\venv\lib\site-packages\sqlalchemy\engine\base.py", line 1799, in _execute_context
    self.dialect.do_execute(
  File "c:\users\usuario\documents\projects\playground\flask_microblog\venv\lib\site-packages\sqlalchemy\engine\default.py", line 717, in do_execute
    cursor.execute(statement, parameters)
sqlalchemy.exc.OperationalError: (sqlite3.OperationalError) no such table: followers
[SQL: SELECT anon_1.post_id AS anon_1_post_id, anon_1.post_body AS anon_1_post_body, anon_1.post_timestamp AS anon_1_post_timestamp, anon_1.post_user_id AS anon_1_post_user_id 
FROM (SELECT post.id AS post_id, post.body AS post_body, post.timestamp AS post_timestamp, post.user_id AS post_user_id 
FROM post JOIN followers ON followers.followed_id = post.user_id 
WHERE followers.follower_id = ? UNION SELECT post.id AS post_id, post.body AS post_body, post.timestamp AS post_timestamp, post.user_id AS post_user_id 
FROM post 
WHERE post.user_id = ?) AS anon_1 ORDER BY anon_1.post_timestamp DESC]
[parameters: (1, 1)]
(Background on this error at: https://sqlalche.me/e/14/e3q8)
2021-10-29 09:38:41,586 INFO: Microblog startup [in C:\Users\usuario\Documents\Projects\playGround\flask_microblog\app\__init__.py:35]
